Not Found: /favicon.ico
Not Found: /
Not Found: /
Not Found: /
Not Found: /
Not Found: /accounts/profile/
[UID:2320][2521538] Child process with pid: 2522711 was killed by signal: 15, core dumped: no
[UID:2320][2521538] Child process with pid: 2522712 was killed by signal: 15, core dumped: no
Invalid HTTP_HOST header: 'www.dressdrive.sebasmd.com'. You may need to add 'www.dressdrive.sebasmd.com' to ALLOWED_HOSTS.
Traceback (most recent call last):
  File "/home/sebasmdc/virtualenv/python_apps/dressdrive/3.10/lib/python3.10/site-packages/django/core/handlers/exception.py", line 55, in inner
    response = get_response(request)
  File "/home/sebasmdc/virtualenv/python_apps/dressdrive/3.10/lib/python3.10/site-packages/django/utils/deprecation.py", line 135, in __call__
    response = self.process_request(request)
  File "/home/sebasmdc/virtualenv/python_apps/dressdrive/3.10/lib/python3.10/site-packages/django/middleware/common.py", line 48, in process_request
    host = request.get_host()
  File "/home/sebasmdc/virtualenv/python_apps/dressdrive/3.10/lib/python3.10/site-packages/django/http/request.py", line 148, in get_host
    raise DisallowedHost(msg)
django.core.exceptions.DisallowedHost: Invalid HTTP_HOST header: 'www.dressdrive.sebasmd.com'. You may need to add 'www.dressdrive.sebasmd.com' to ALLOWED_HOSTS.
Invalid HTTP_HOST header: 'www.dressdrive.sebasmd.com'. You may need to add 'www.dressdrive.sebasmd.com' to ALLOWED_HOSTS.
Traceback (most recent call last):
  File "/home/sebasmdc/virtualenv/python_apps/dressdrive/3.10/lib/python3.10/site-packages/django/core/handlers/exception.py", line 55, in inner
    response = get_response(request)
  File "/home/sebasmdc/virtualenv/python_apps/dressdrive/3.10/lib/python3.10/site-packages/django/utils/deprecation.py", line 135, in __call__
    response = self.process_request(request)
  File "/home/sebasmdc/virtualenv/python_apps/dressdrive/3.10/lib/python3.10/site-packages/django/middleware/common.py", line 48, in process_request
    host = request.get_host()
  File "/home/sebasmdc/virtualenv/python_apps/dressdrive/3.10/lib/python3.10/site-packages/django/http/request.py", line 148, in get_host
    raise DisallowedHost(msg)
django.core.exceptions.DisallowedHost: Invalid HTTP_HOST header: 'www.dressdrive.sebasmd.com'. You may need to add 'www.dressdrive.sebasmd.com' to ALLOWED_HOSTS.
Not Found: /
Not Found: /
Bad Request: /
Bad Request: /
Invalid HTTP_HOST header: 'www.dressdrive.sebasmd.com'. You may need to add 'www.dressdrive.sebasmd.com' to ALLOWED_HOSTS.
Traceback (most recent call last):
  File "/home/sebasmdc/virtualenv/python_apps/dressdrive/3.10/lib/python3.10/site-packages/django/core/handlers/exception.py", line 55, in inner
    response = get_response(request)
  File "/home/sebasmdc/virtualenv/python_apps/dressdrive/3.10/lib/python3.10/site-packages/django/utils/deprecation.py", line 135, in __call__
    response = self.process_request(request)
  File "/home/sebasmdc/virtualenv/python_apps/dressdrive/3.10/lib/python3.10/site-packages/django/middleware/common.py", line 48, in process_request
    host = request.get_host()
  File "/home/sebasmdc/virtualenv/python_apps/dressdrive/3.10/lib/python3.10/site-packages/django/http/request.py", line 148, in get_host
    raise DisallowedHost(msg)
django.core.exceptions.DisallowedHost: Invalid HTTP_HOST header: 'www.dressdrive.sebasmd.com'. You may need to add 'www.dressdrive.sebasmd.com' to ALLOWED_HOSTS.
Bad Request: /
Invalid HTTP_HOST header: 'www.dressdrive.sebasmd.com'. You may need to add 'www.dressdrive.sebasmd.com' to ALLOWED_HOSTS.
Traceback (most recent call last):
  File "/home/sebasmdc/virtualenv/python_apps/dressdrive/3.10/lib/python3.10/site-packages/django/core/handlers/exception.py", line 55, in inner
    response = get_response(request)
  File "/home/sebasmdc/virtualenv/python_apps/dressdrive/3.10/lib/python3.10/site-packages/django/utils/deprecation.py", line 135, in __call__
    response = self.process_request(request)
  File "/home/sebasmdc/virtualenv/python_apps/dressdrive/3.10/lib/python3.10/site-packages/django/middleware/common.py", line 48, in process_request
    host = request.get_host()
  File "/home/sebasmdc/virtualenv/python_apps/dressdrive/3.10/lib/python3.10/site-packages/django/http/request.py", line 148, in get_host
    raise DisallowedHost(msg)
django.core.exceptions.DisallowedHost: Invalid HTTP_HOST header: 'www.dressdrive.sebasmd.com'. You may need to add 'www.dressdrive.sebasmd.com' to ALLOWED_HOSTS.
Bad Request: /
Not Found: /
Invalid HTTP_HOST header: 'www.dressdrive.sebasmd.com'. You may need to add 'www.dressdrive.sebasmd.com' to ALLOWED_HOSTS.
Traceback (most recent call last):
  File "/home/sebasmdc/virtualenv/python_apps/dressdrive/3.10/lib/python3.10/site-packages/django/core/handlers/exception.py", line 55, in inner
    response = get_response(request)
  File "/home/sebasmdc/virtualenv/python_apps/dressdrive/3.10/lib/python3.10/site-packages/django/utils/deprecation.py", line 135, in __call__
    response = self.process_request(request)
  File "/home/sebasmdc/virtualenv/python_apps/dressdrive/3.10/lib/python3.10/site-packages/django/middleware/common.py", line 48, in process_request
    host = request.get_host()
  File "/home/sebasmdc/virtualenv/python_apps/dressdrive/3.10/lib/python3.10/site-packages/django/http/request.py", line 148, in get_host
    raise DisallowedHost(msg)
django.core.exceptions.DisallowedHost: Invalid HTTP_HOST header: 'www.dressdrive.sebasmd.com'. You may need to add 'www.dressdrive.sebasmd.com' to ALLOWED_HOSTS.
Bad Request: /favicon.ico
Invalid HTTP_HOST header: 'www.dressdrive.sebasmd.com'. You may need to add 'www.dressdrive.sebasmd.com' to ALLOWED_HOSTS.
Traceback (most recent call last):
  File "/home/sebasmdc/virtualenv/python_apps/dressdrive/3.10/lib/python3.10/site-packages/django/core/handlers/exception.py", line 55, in inner
    response = get_response(request)
  File "/home/sebasmdc/virtualenv/python_apps/dressdrive/3.10/lib/python3.10/site-packages/django/utils/deprecation.py", line 135, in __call__
    response = self.process_request(request)
  File "/home/sebasmdc/virtualenv/python_apps/dressdrive/3.10/lib/python3.10/site-packages/django/middleware/common.py", line 48, in process_request
    host = request.get_host()
  File "/home/sebasmdc/virtualenv/python_apps/dressdrive/3.10/lib/python3.10/site-packages/django/http/request.py", line 148, in get_host
    raise DisallowedHost(msg)
django.core.exceptions.DisallowedHost: Invalid HTTP_HOST header: 'www.dressdrive.sebasmd.com'. You may need to add 'www.dressdrive.sebasmd.com' to ALLOWED_HOSTS.
Bad Request: /favicon.ico
Invalid HTTP_HOST header: 'www.dressdrive.sebasmd.com'. You may need to add 'www.dressdrive.sebasmd.com' to ALLOWED_HOSTS.
Traceback (most recent call last):
  File "/home/sebasmdc/virtualenv/python_apps/dressdrive/3.10/lib/python3.10/site-packages/django/core/handlers/exception.py", line 55, in inner
    response = get_response(request)
  File "/home/sebasmdc/virtualenv/python_apps/dressdrive/3.10/lib/python3.10/site-packages/django/utils/deprecation.py", line 135, in __call__
    response = self.process_request(request)
  File "/home/sebasmdc/virtualenv/python_apps/dressdrive/3.10/lib/python3.10/site-packages/django/middleware/common.py", line 48, in process_request
    host = request.get_host()
  File "/home/sebasmdc/virtualenv/python_apps/dressdrive/3.10/lib/python3.10/site-packages/django/http/request.py", line 148, in get_host
    raise DisallowedHost(msg)
django.core.exceptions.DisallowedHost: Invalid HTTP_HOST header: 'www.dressdrive.sebasmd.com'. You may need to add 'www.dressdrive.sebasmd.com' to ALLOWED_HOSTS.
Bad Request: /favicon.png
Invalid HTTP_HOST header: 'www.dressdrive.sebasmd.com'. You may need to add 'www.dressdrive.sebasmd.com' to ALLOWED_HOSTS.
Traceback (most recent call last):
  File "/home/sebasmdc/virtualenv/python_apps/dressdrive/3.10/lib/python3.10/site-packages/django/core/handlers/exception.py", line 55, in inner
    response = get_response(request)
  File "/home/sebasmdc/virtualenv/python_apps/dressdrive/3.10/lib/python3.10/site-packages/django/utils/deprecation.py", line 135, in __call__
    response = self.process_request(request)
  File "/home/sebasmdc/virtualenv/python_apps/dressdrive/3.10/lib/python3.10/site-packages/django/middleware/common.py", line 48, in process_request
    host = request.get_host()
  File "/home/sebasmdc/virtualenv/python_apps/dressdrive/3.10/lib/python3.10/site-packages/django/http/request.py", line 148, in get_host
    raise DisallowedHost(msg)
django.core.exceptions.DisallowedHost: Invalid HTTP_HOST header: 'www.dressdrive.sebasmd.com'. You may need to add 'www.dressdrive.sebasmd.com' to ALLOWED_HOSTS.
Bad Request: /favicon.png
Not Found: /favicon.ico
Not Found: /favicon.png
Not Found: /
Invalid HTTP_HOST header: 'www.dressdrive.sebasmd.com'. You may need to add 'www.dressdrive.sebasmd.com' to ALLOWED_HOSTS.
Traceback (most recent call last):
  File "/home/sebasmdc/virtualenv/python_apps/dressdrive/3.10/lib/python3.10/site-packages/django/core/handlers/exception.py", line 55, in inner
    response = get_response(request)
  File "/home/sebasmdc/virtualenv/python_apps/dressdrive/3.10/lib/python3.10/site-packages/django/utils/deprecation.py", line 135, in __call__
    response = self.process_request(request)
  File "/home/sebasmdc/virtualenv/python_apps/dressdrive/3.10/lib/python3.10/site-packages/django/middleware/common.py", line 48, in process_request
    host = request.get_host()
  File "/home/sebasmdc/virtualenv/python_apps/dressdrive/3.10/lib/python3.10/site-packages/django/http/request.py", line 148, in get_host
    raise DisallowedHost(msg)
django.core.exceptions.DisallowedHost: Invalid HTTP_HOST header: 'www.dressdrive.sebasmd.com'. You may need to add 'www.dressdrive.sebasmd.com' to ALLOWED_HOSTS.
Bad Request: /
Invalid HTTP_HOST header: 'www.dressdrive.sebasmd.com'. You may need to add 'www.dressdrive.sebasmd.com' to ALLOWED_HOSTS.
Traceback (most recent call last):
  File "/home/sebasmdc/virtualenv/python_apps/dressdrive/3.10/lib/python3.10/site-packages/django/core/handlers/exception.py", line 55, in inner
    response = get_response(request)
  File "/home/sebasmdc/virtualenv/python_apps/dressdrive/3.10/lib/python3.10/site-packages/django/utils/deprecation.py", line 135, in __call__
    response = self.process_request(request)
  File "/home/sebasmdc/virtualenv/python_apps/dressdrive/3.10/lib/python3.10/site-packages/django/middleware/common.py", line 48, in process_request
    host = request.get_host()
  File "/home/sebasmdc/virtualenv/python_apps/dressdrive/3.10/lib/python3.10/site-packages/django/http/request.py", line 148, in get_host
    raise DisallowedHost(msg)
django.core.exceptions.DisallowedHost: Invalid HTTP_HOST header: 'www.dressdrive.sebasmd.com'. You may need to add 'www.dressdrive.sebasmd.com' to ALLOWED_HOSTS.
Bad Request: /
Not Found: /
Not Found: /favicon.png
Not Found: /favicon.ico
Not Found: /
Invalid HTTP_HOST header: 'www.dressdrive.sebasmd.com'. You may need to add 'www.dressdrive.sebasmd.com' to ALLOWED_HOSTS.
Traceback (most recent call last):
  File "/home/sebasmdc/virtualenv/python_apps/dressdrive/3.10/lib/python3.10/site-packages/django/core/handlers/exception.py", line 55, in inner
    response = get_response(request)
  File "/home/sebasmdc/virtualenv/python_apps/dressdrive/3.10/lib/python3.10/site-packages/django/utils/deprecation.py", line 135, in __call__
    response = self.process_request(request)
  File "/home/sebasmdc/virtualenv/python_apps/dressdrive/3.10/lib/python3.10/site-packages/django/middleware/common.py", line 48, in process_request
    host = request.get_host()
  File "/home/sebasmdc/virtualenv/python_apps/dressdrive/3.10/lib/python3.10/site-packages/django/http/request.py", line 148, in get_host
    raise DisallowedHost(msg)
django.core.exceptions.DisallowedHost: Invalid HTTP_HOST header: 'www.dressdrive.sebasmd.com'. You may need to add 'www.dressdrive.sebasmd.com' to ALLOWED_HOSTS.
Bad Request: /
Not Found: /favicon.ico
Not Found: /
Not Found: /
Not Found: /
Not Found: /
Not Found: /favicon.ico
Invalid HTTP_HOST header: 'www.dressdrive.sebasmd.com'. You may need to add 'www.dressdrive.sebasmd.com' to ALLOWED_HOSTS.
Traceback (most recent call last):
  File "/home/sebasmdc/virtualenv/python_apps/dressdrive/3.10/lib/python3.10/site-packages/django/core/handlers/exception.py", line 55, in inner
    response = get_response(request)
  File "/home/sebasmdc/virtualenv/python_apps/dressdrive/3.10/lib/python3.10/site-packages/django/utils/deprecation.py", line 135, in __call__
    response = self.process_request(request)
  File "/home/sebasmdc/virtualenv/python_apps/dressdrive/3.10/lib/python3.10/site-packages/django/middleware/common.py", line 48, in process_request
    host = request.get_host()
  File "/home/sebasmdc/virtualenv/python_apps/dressdrive/3.10/lib/python3.10/site-packages/django/http/request.py", line 148, in get_host
    raise DisallowedHost(msg)
django.core.exceptions.DisallowedHost: Invalid HTTP_HOST header: 'www.dressdrive.sebasmd.com'. You may need to add 'www.dressdrive.sebasmd.com' to ALLOWED_HOSTS.
Not Found: /
Bad Request: /
Not Found: /robots.txt
Not Found: /favicon.ico
Not Found: /
Not Found: /robots.txt
Not Found: /
Not Found: /
Not Found: /
Not Found: /favicon.ico
Traceback (most recent call last):
  File "/home/sebasmdc/python_apps/dressdrive/passenger_wsgi.py", line 1, in <module>
    from app_core_dressdrive.wsgi import application
  File "/home/sebasmdc/python_apps/dressdrive/app_core_dressdrive/wsgi.py", line 16, in <module>
    application = get_wsgi_application()
  File "/home/sebasmdc/virtualenv/python_apps/dressdrive/3.10/lib/python3.10/site-packages/django/core/wsgi.py", line 12, in get_wsgi_application
    django.setup(set_prefix=False)
  File "/home/sebasmdc/virtualenv/python_apps/dressdrive/3.10/lib/python3.10/site-packages/django/__init__.py", line 19, in setup
    configure_logging(settings.LOGGING_CONFIG, settings.LOGGING)
  File "/home/sebasmdc/virtualenv/python_apps/dressdrive/3.10/lib/python3.10/site-packages/django/conf/__init__.py", line 92, in __getattr__
    self._setup(name)
  File "/home/sebasmdc/virtualenv/python_apps/dressdrive/3.10/lib/python3.10/site-packages/django/conf/__init__.py", line 79, in _setup
    self._wrapped = Settings(settings_module)
  File "/home/sebasmdc/virtualenv/python_apps/dressdrive/3.10/lib/python3.10/site-packages/django/conf/__init__.py", line 190, in __init__
    mod = importlib.import_module(self.SETTINGS_MODULE)
  File "/opt/alt/python310/lib64/python3.10/importlib/__init__.py", line 126, in import_module
    return _bootstrap._gcd_import(name[level:], package, level)
  File "/home/sebasmdc/python_apps/dressdrive/app_core_dressdrive/settings.py", line 293, in <module>
    SOCIALACCOUNT_PROVIDERS = ast.literal_eval(
  File "/opt/alt/python310/lib64/python3.10/ast.py", line 108, in literal_eval
    return _convert(node_or_string)
  File "/opt/alt/python310/lib64/python3.10/ast.py", line 107, in _convert
    return _convert_signed_num(node)
  File "/opt/alt/python310/lib64/python3.10/ast.py", line 81, in _convert_signed_num
    return _convert_num(node)
  File "/opt/alt/python310/lib64/python3.10/ast.py", line 72, in _convert_num
    _raise_malformed_node(node)
  File "/opt/alt/python310/lib64/python3.10/ast.py", line 69, in _raise_malformed_node
    raise ValueError(msg + f': {node!r}')
ValueError: malformed node or string: None
Traceback (most recent call last):
  File "/home/sebasmdc/python_apps/dressdrive/passenger_wsgi.py", line 1, in <module>
    from app_core_dressdrive.wsgi import application
  File "/home/sebasmdc/python_apps/dressdrive/app_core_dressdrive/wsgi.py", line 16, in <module>
    application = get_wsgi_application()
  File "/home/sebasmdc/virtualenv/python_apps/dressdrive/3.10/lib/python3.10/site-packages/django/core/wsgi.py", line 12, in get_wsgi_application
    django.setup(set_prefix=False)
  File "/home/sebasmdc/virtualenv/python_apps/dressdrive/3.10/lib/python3.10/site-packages/django/__init__.py", line 19, in setup
    configure_logging(settings.LOGGING_CONFIG, settings.LOGGING)
  File "/home/sebasmdc/virtualenv/python_apps/dressdrive/3.10/lib/python3.10/site-packages/django/conf/__init__.py", line 92, in __getattr__
    self._setup(name)
  File "/home/sebasmdc/virtualenv/python_apps/dressdrive/3.10/lib/python3.10/site-packages/django/conf/__init__.py", line 79, in _setup
    self._wrapped = Settings(settings_module)
  File "/home/sebasmdc/virtualenv/python_apps/dressdrive/3.10/lib/python3.10/site-packages/django/conf/__init__.py", line 190, in __init__
    mod = importlib.import_module(self.SETTINGS_MODULE)
  File "/opt/alt/python310/lib64/python3.10/importlib/__init__.py", line 126, in import_module
    return _bootstrap._gcd_import(name[level:], package, level)
  File "/home/sebasmdc/python_apps/dressdrive/app_core_dressdrive/settings.py", line 293, in <module>
    SOCIALACCOUNT_PROVIDERS = ast.literal_eval(
  File "/opt/alt/python310/lib64/python3.10/ast.py", line 108, in literal_eval
    return _convert(node_or_string)
  File "/opt/alt/python310/lib64/python3.10/ast.py", line 107, in _convert
    return _convert_signed_num(node)
  File "/opt/alt/python310/lib64/python3.10/ast.py", line 81, in _convert_signed_num
    return _convert_num(node)
  File "/opt/alt/python310/lib64/python3.10/ast.py", line 72, in _convert_num
    _raise_malformed_node(node)
  File "/opt/alt/python310/lib64/python3.10/ast.py", line 69, in _raise_malformed_node
    raise ValueError(msg + f': {node!r}')
ValueError: malformed node or string: None
[UID:2320][481455] Child process with pid: 481525 was killed by signal: 15, core dumped: no
Traceback (most recent call last):
  File "/home/sebasmdc/python_apps/dressdrive/passenger_wsgi.py", line 1, in <module>
    from app_core_dressdrive.wsgi import application
  File "/home/sebasmdc/python_apps/dressdrive/app_core_dressdrive/wsgi.py", line 16, in <module>
    application = get_wsgi_application()
  File "/home/sebasmdc/virtualenv/python_apps/dressdrive/3.10/lib/python3.10/site-packages/django/core/wsgi.py", line 12, in get_wsgi_application
    django.setup(set_prefix=False)
  File "/home/sebasmdc/virtualenv/python_apps/dressdrive/3.10/lib/python3.10/site-packages/django/__init__.py", line 19, in setup
    configure_logging(settings.LOGGING_CONFIG, settings.LOGGING)
  File "/home/sebasmdc/virtualenv/python_apps/dressdrive/3.10/lib/python3.10/site-packages/django/conf/__init__.py", line 92, in __getattr__
    self._setup(name)
  File "/home/sebasmdc/virtualenv/python_apps/dressdrive/3.10/lib/python3.10/site-packages/django/conf/__init__.py", line 79, in _setup
    self._wrapped = Settings(settings_module)
  File "/home/sebasmdc/virtualenv/python_apps/dressdrive/3.10/lib/python3.10/site-packages/django/conf/__init__.py", line 190, in __init__
    mod = importlib.import_module(self.SETTINGS_MODULE)
  File "/opt/alt/python310/lib64/python3.10/importlib/__init__.py", line 126, in import_module
    return _bootstrap._gcd_import(name[level:], package, level)
  File "/home/sebasmdc/python_apps/dressdrive/app_core_dressdrive/settings.py", line 293, in <module>
    SOCIALACCOUNT_PROVIDERS = ast.literal_eval(
  File "/opt/alt/python310/lib64/python3.10/ast.py", line 108, in literal_eval
    return _convert(node_or_string)
  File "/opt/alt/python310/lib64/python3.10/ast.py", line 107, in _convert
    return _convert_signed_num(node)
  File "/opt/alt/python310/lib64/python3.10/ast.py", line 81, in _convert_signed_num
    return _convert_num(node)
  File "/opt/alt/python310/lib64/python3.10/ast.py", line 72, in _convert_num
    _raise_malformed_node(node)
  File "/opt/alt/python310/lib64/python3.10/ast.py", line 69, in _raise_malformed_node
    raise ValueError(msg + f': {node!r}')
ValueError: malformed node or string: None
[UID:2320][481455] Child process with pid: 481759 was killed by signal: 15, core dumped: no
Traceback (most recent call last):
  File "/home/sebasmdc/python_apps/dressdrive/passenger_wsgi.py", line 1, in <module>
    from app_core_dressdrive.wsgi import application
  File "/home/sebasmdc/python_apps/dressdrive/app_core_dressdrive/wsgi.py", line 16, in <module>
    application = get_wsgi_application()
  File "/home/sebasmdc/virtualenv/python_apps/dressdrive/3.10/lib/python3.10/site-packages/django/core/wsgi.py", line 12, in get_wsgi_application
    django.setup(set_prefix=False)
  File "/home/sebasmdc/virtualenv/python_apps/dressdrive/3.10/lib/python3.10/site-packages/django/__init__.py", line 19, in setup
    configure_logging(settings.LOGGING_CONFIG, settings.LOGGING)
  File "/home/sebasmdc/virtualenv/python_apps/dressdrive/3.10/lib/python3.10/site-packages/django/conf/__init__.py", line 92, in __getattr__
    self._setup(name)
  File "/home/sebasmdc/virtualenv/python_apps/dressdrive/3.10/lib/python3.10/site-packages/django/conf/__init__.py", line 79, in _setup
    self._wrapped = Settings(settings_module)
  File "/home/sebasmdc/virtualenv/python_apps/dressdrive/3.10/lib/python3.10/site-packages/django/conf/__init__.py", line 190, in __init__
    mod = importlib.import_module(self.SETTINGS_MODULE)
  File "/opt/alt/python310/lib64/python3.10/importlib/__init__.py", line 126, in import_module
    return _bootstrap._gcd_import(name[level:], package, level)
  File "/home/sebasmdc/python_apps/dressdrive/app_core_dressdrive/settings.py", line 293, in <module>
    SOCIALACCOUNT_PROVIDERS = ast.literal_eval(
  File "/opt/alt/python310/lib64/python3.10/ast.py", line 108, in literal_eval
    return _convert(node_or_string)
  File "/opt/alt/python310/lib64/python3.10/ast.py", line 107, in _convert
    return _convert_signed_num(node)
  File "/opt/alt/python310/lib64/python3.10/ast.py", line 81, in _convert_signed_num
    return _convert_num(node)
  File "/opt/alt/python310/lib64/python3.10/ast.py", line 72, in _convert_num
    _raise_malformed_node(node)
  File "/opt/alt/python310/lib64/python3.10/ast.py", line 69, in _raise_malformed_node
    raise ValueError(msg + f': {node!r}')
ValueError: malformed node or string: None
[UID:2320][481455] Child process with pid: 481857 was killed by signal: 15, core dumped: no
Traceback (most recent call last):
  File "/home/sebasmdc/python_apps/dressdrive/passenger_wsgi.py", line 1, in <module>
    from app_core_dressdrive.wsgi import application
  File "/home/sebasmdc/python_apps/dressdrive/app_core_dressdrive/wsgi.py", line 16, in <module>
    application = get_wsgi_application()
  File "/home/sebasmdc/virtualenv/python_apps/dressdrive/3.10/lib/python3.10/site-packages/django/core/wsgi.py", line 12, in get_wsgi_application
    django.setup(set_prefix=False)
  File "/home/sebasmdc/virtualenv/python_apps/dressdrive/3.10/lib/python3.10/site-packages/django/__init__.py", line 19, in setup
    configure_logging(settings.LOGGING_CONFIG, settings.LOGGING)
  File "/home/sebasmdc/virtualenv/python_apps/dressdrive/3.10/lib/python3.10/site-packages/django/conf/__init__.py", line 92, in __getattr__
    self._setup(name)
  File "/home/sebasmdc/virtualenv/python_apps/dressdrive/3.10/lib/python3.10/site-packages/django/conf/__init__.py", line 79, in _setup
    self._wrapped = Settings(settings_module)
  File "/home/sebasmdc/virtualenv/python_apps/dressdrive/3.10/lib/python3.10/site-packages/django/conf/__init__.py", line 190, in __init__
    mod = importlib.import_module(self.SETTINGS_MODULE)
  File "/opt/alt/python310/lib64/python3.10/importlib/__init__.py", line 126, in import_module
    return _bootstrap._gcd_import(name[level:], package, level)
  File "/home/sebasmdc/python_apps/dressdrive/app_core_dressdrive/settings.py", line 293, in <module>
    SOCIALACCOUNT_PROVIDERS = ast.literal_eval(
  File "/opt/alt/python310/lib64/python3.10/ast.py", line 108, in literal_eval
    return _convert(node_or_string)
  File "/opt/alt/python310/lib64/python3.10/ast.py", line 107, in _convert
    return _convert_signed_num(node)
  File "/opt/alt/python310/lib64/python3.10/ast.py", line 81, in _convert_signed_num
    return _convert_num(node)
  File "/opt/alt/python310/lib64/python3.10/ast.py", line 72, in _convert_num
    _raise_malformed_node(node)
  File "/opt/alt/python310/lib64/python3.10/ast.py", line 69, in _raise_malformed_node
    raise ValueError(msg + f': {node!r}')
ValueError: malformed node or string: None
[UID:2320][481455] Child process with pid: 481872 was killed by signal: 15, core dumped: no
